<?xml version="1.0" encoding="UTF-8"?>
<robot xmlns:xacro="http://www.ros.org/wiki/xacro">
  <xacro:macro name="denso_robot_arm_kinematics" params="namespace model">

    <gazebo>
      <plugin name="gazebo_ros_control" filename="libgazebo_ros_control.so">
        <robotNamespace>/$(arg namespace)</robotNamespace>
      </plugin>
    </gazebo>

    <link name="$(arg namespace)base_link">
      <visual>
        <origin xyz="0.000000 0.000000 0.000000" rpy="0.000000 0.000000 0.000000"/>
        <geometry>
          <mesh filename="file://$(find denso_robot_descriptions)/robots/$(arg model)/meshes/base_link.dae" scale="1 1 1"/>
        </geometry>
      </visual>
      <collision>
        <origin xyz="0.000000 0.000000 0.000000" rpy="0.000000 0.000000 0.000000"/>
        <geometry>
          <mesh filename="file://$(find denso_robot_descriptions)/robots/$(arg model)/meshes/base_link.dae" scale="1 1 1"/>
        </geometry>
      </collision>
      <inertial>
        <mass value="1"/>
        <origin xyz="0.000000 0.000000 0.000000" rpy="0.000000 0.000000 0.000000"/>
        <inertia ixx="1" ixy="0" ixz="0" iyy="1" iyz="0" izz="1"/>
      </inertial>
    </link>

    <link name="$(arg namespace)J1">
      <visual>
        <origin xyz="0.000000 0.000000 0.000000" rpy="0.000000 0.000000 0.000000"/>
        <geometry>
          <mesh filename="file://$(find denso_robot_descriptions)/robots/$(arg model)/meshes/J1.dae" scale="1 1 1"/>
        </geometry>
      </visual>
      <collision>
        <origin xyz="0.000000 0.000000 0.000000" rpy="0.000000 0.000000 0.000000"/>
        <geometry>
          <mesh filename="file://$(find denso_robot_descriptions)/robots/$(arg model)/meshes/J1.dae" scale="1 1 1"/>
        </geometry>
      </collision>
      <inertial>
        <mass value="1"/>
        <origin xyz="0.000000 0.000000 0.000000" rpy="0.000000 0.000000 0.000000"/>
        <inertia ixx="1" ixy="0" ixz="0" iyy="1" iyz="0" izz="1"/>
      </inertial>
    </link>

    <joint name="$(arg namespace)joint_1" type="revolute">
      <parent link="$(arg namespace)base_link"/>
      <child link="$(arg namespace)J1"/>
      <origin xyz="0.000000 0.000000 0.000000" rpy="0.000000 0.000000 0.000000"/>
      <axis xyz="-0.000000 -0.000000 1.000000"/>
      <limit effort="1" lower="-2.79252680319093" upper="2.79252680319093" velocity="1"/>
      <dynamics damping="0" friction="0"/>
    </joint>

    <link name="$(arg namespace)J2">
      <visual>
        <origin xyz="0.000000 0.000000 0.000000" rpy="0.000000 0.000000 0.000000"/>
        <geometry>
          <mesh filename="file://$(find denso_robot_descriptions)/robots/$(arg model)/meshes/J2.dae" scale="1 1 1"/>
        </geometry>
      </visual>
      <collision>
        <origin xyz="0.000000 0.000000 0.000000" rpy="0.000000 0.000000 0.000000"/>
        <geometry>
          <mesh filename="file://$(find denso_robot_descriptions)/robots/$(arg model)/meshes/J2.dae" scale="1 1 1"/>
        </geometry>
      </collision>
      <inertial>
        <mass value="1"/>
        <origin xyz="0.000000 0.000000 0.000000" rpy="0.000000 0.000000 0.000000"/>
        <inertia ixx="1" ixy="0" ixz="0" iyy="1" iyz="0" izz="1"/>
      </inertial>
    </link>

    <joint name="$(arg namespace)joint_2" type="revolute">
      <parent link="$(arg namespace)J1"/>
      <child link="$(arg namespace)J2"/>
      <origin xyz="0.000000 0.000000 0.280000" rpy="0.000000 0.000000 0.000000"/>
      <axis xyz="-0.000000 1.000000 -0.000000"/>
      <limit effort="1" lower="-2.0943951023932" upper="2.0943951023932" velocity="1"/>
      <dynamics damping="0" friction="0"/>
    </joint>

    <link name="$(arg namespace)J3">
      <visual>
        <origin xyz="0.000000 0.000000 0.000000" rpy="0.000000 0.000000 0.000000"/>
        <geometry>
          <mesh filename="file://$(find denso_robot_descriptions)/robots/$(arg model)/meshes/J3.dae" scale="1 1 1"/>
        </geometry>
      </visual>
      <collision>
        <origin xyz="0.000000 0.000000 0.000000" rpy="0.000000 0.000000 0.000000"/>
        <geometry>
          <mesh filename="file://$(find denso_robot_descriptions)/robots/$(arg model)/meshes/J3.dae" scale="1 1 1"/>
        </geometry>
      </collision>
      <inertial>
        <mass value="1"/>
        <origin xyz="0.000000 0.000000 0.000000" rpy="0.000000 0.000000 0.000000"/>
        <inertia ixx="1" ixy="0" ixz="0" iyy="1" iyz="0" izz="1"/>
      </inertial>
    </link>

    <joint name="$(arg namespace)joint_3" type="revolute">
      <parent link="$(arg namespace)J2"/>
      <child link="$(arg namespace)J3"/>
      <origin xyz="0.000000 0.000000 0.210000" rpy="0.000000 0.000000 0.000000"/>
      <axis xyz="-0.000000 1.000000 -0.000000"/>
      <limit effort="1" lower="0.331612557878923" upper="2.79252680319093" velocity="1"/>
      <dynamics damping="0" friction="0"/>
    </joint>

    <link name="$(arg namespace)J4">
      <visual>
        <origin xyz="0.000000 0.000000 0.000000" rpy="0.000000 0.000000 0.000000"/>
        <geometry>
          <mesh filename="file://$(find denso_robot_descriptions)/robots/$(arg model)/meshes/J4.dae" scale="1 1 1"/>
        </geometry>
      </visual>
      <collision>
        <origin xyz="0.000000 0.000000 0.000000" rpy="0.000000 0.000000 0.000000"/>
        <geometry>
          <mesh filename="file://$(find denso_robot_descriptions)/robots/$(arg model)/meshes/J4.dae" scale="1 1 1"/>
        </geometry>
      </collision>
      <inertial>
        <mass value="1"/>
        <origin xyz="0.000000 0.000000 0.000000" rpy="0.000000 0.000000 0.000000"/>
        <inertia ixx="1" ixy="0" ixz="0" iyy="1" iyz="0" izz="1"/>
      </inertial>
    </link>

    <joint name="$(arg namespace)joint_4" type="revolute">
      <parent link="$(arg namespace)J3"/>
      <child link="$(arg namespace)J4"/>
      <origin xyz="-0.075000 0.000000 -0.490000" rpy="0.000000 0.000000 0.000000"/>
      <axis xyz="-0.000000 -0.000000 1.000000"/>
      <limit effort="1" lower="-2.79252680319093" upper="2.79252680319093" velocity="1"/>
      <dynamics damping="0" friction="0"/>
    </joint>

    <link name="$(arg namespace)J5">
      <visual>
        <origin xyz="0.000000 0.000000 0.000000" rpy="0.000000 0.000000 0.000000"/>
        <geometry>
          <mesh filename="file://$(find denso_robot_descriptions)/robots/$(arg model)/meshes/J5.dae" scale="1 1 1"/>
        </geometry>
      </visual>
      <collision>
        <origin xyz="0.000000 0.000000 0.000000" rpy="0.000000 0.000000 0.000000"/>
        <geometry>
          <mesh filename="file://$(find denso_robot_descriptions)/robots/$(arg model)/meshes/J5.dae" scale="1 1 1"/>
        </geometry>
      </collision>
      <inertial>
        <mass value="1"/>
        <origin xyz="0.000000 0.000000 0.000000" rpy="0.000000 0.000000 0.000000"/>
        <inertia ixx="1" ixy="0" ixz="0" iyy="1" iyz="0" izz="1"/>
      </inertial>
    </link>

    <joint name="$(arg namespace)joint_5" type="revolute">
      <parent link="$(arg namespace)J4"/>
      <child link="$(arg namespace)J5"/>
      <origin xyz="0.000000 0.000000 0.700000" rpy="0.000000 0.000000 0.000000"/>
      <axis xyz="-0.000000 1.000000 -0.000000"/>
      <limit effort="1" lower="-2.0943951023932" upper="2.0943951023932" velocity="1"/>
      <dynamics damping="0" friction="0"/>
    </joint>

    <link name="$(arg namespace)J6">
      <visual>
        <origin xyz="0.000000 0.000000 0.000000" rpy="0.000000 0.000000 0.000000"/>
        <geometry>
          <mesh filename="file://$(find denso_robot_descriptions)/robots/$(arg model)/meshes/J6.dae" scale="1 1 1"/>
        </geometry>
      </visual>
      <collision>
        <origin xyz="0.000000 0.000000 0.000000" rpy="0.000000 0.000000 0.000000"/>
        <geometry>
          <mesh filename="file://$(find denso_robot_descriptions)/robots/$(arg model)/meshes/J6.dae" scale="1 1 1"/>
        </geometry>
      </collision>
      <inertial>
        <mass value="1"/>
        <origin xyz="0.000000 0.000000 0.000000" rpy="0.000000 0.000000 0.000000"/>
        <inertia ixx="1" ixy="0" ixz="0" iyy="1" iyz="0" izz="1"/>
      </inertial>
    </link>

    <joint name="$(arg namespace)joint_6" type="revolute">
      <parent link="$(arg namespace)J5"/>
      <child link="$(arg namespace)J6"/>
      <origin xyz="0.000000 0.000000 0.53000" rpy="0.000000 0.000000 0.000000"/>
      <axis xyz="-0.000000 -0.000000 1.000000"/>
      <limit effort="1" lower="-6.28318530717959" upper="6.28318530717959" velocity="1"/>
      <dynamics damping="0" friction="0"/>
    </joint>

  </xacro:macro>
</robot>

